Traceback (most recent call last):
  File "/nfs/team205/ed6/bin/sc_target_evidence/src/process_sc_data.py", line 263, in <module>
    adata = get_disease_targets_sc_data(
            ^^^^^^^^^^^^^^^^^^^^^^^^^^^^
  File "/nfs/team205/ed6/bin/sc_target_evidence/src/process_sc_data.py", line 90, in get_disease_targets_sc_data
    sc_metadata = _get_cxg_datasets(cxg_metadata, disease_ontology_id, keep_disease_relevant_tissue, keep_normal)
                  ^^^^^^^^^^^^^^^^^^^^^^^^^^^^^^^^^^^^^^^^^^^^^^^^^^^^^^^^^^^^^^^^^^^^^^^^^^^^^^^^^^^^^^^^^^^^^^^
  File "/nfs/team205/ed6/bin/sc_target_evidence/src/process_sc_data.py", line 43, in _get_cxg_datasets
    normal_metadata = cxg_metadata[ (cxg_metadata['disease_ontology_id'] == 'PATO:0000461') & (cxg_metadata['tissue_general'] == filt_metadata['disease_relevant_tissue'].iloc[0]) ]
                                                                                                                                 ~~~~~~~~~~~~~~~~~~~~~~~~~~~~~~~~~~~~~~~~~~~~~^^^
  File "/nfs/team205/ed6/miniconda3/envs/sc-target-evidence-env/lib/python3.11/site-packages/pandas/core/indexing.py", line 1103, in __getitem__
    return self._getitem_axis(maybe_callable, axis=axis)
           ^^^^^^^^^^^^^^^^^^^^^^^^^^^^^^^^^^^^^^^^^^^^^
  File "/nfs/team205/ed6/miniconda3/envs/sc-target-evidence-env/lib/python3.11/site-packages/pandas/core/indexing.py", line 1656, in _getitem_axis
    self._validate_integer(key, axis)
  File "/nfs/team205/ed6/miniconda3/envs/sc-target-evidence-env/lib/python3.11/site-packages/pandas/core/indexing.py", line 1589, in _validate_integer
    raise IndexError("single positional indexer is out-of-bounds")
IndexError: single positional indexer is out-of-bounds
